[2018-06-04 17:59:26,854] [15455] {/home/razor/TruckNLoad/Truck-n-Load/venv/lib/python3.6/site-packages/flask/app.py:1761} ERROR - Exception on /pan_preparation [POST]
Traceback (most recent call last):
  File "/home/razor/TruckNLoad/Truck-n-Load/venv/lib/python3.6/site-packages/flask/app.py", line 2292, in wsgi_app
    response = self.full_dispatch_request()
  File "/home/razor/TruckNLoad/Truck-n-Load/venv/lib/python3.6/site-packages/flask/app.py", line 1815, in full_dispatch_request
    rv = self.handle_user_exception(e)
  File "/home/razor/TruckNLoad/Truck-n-Load/venv/lib/python3.6/site-packages/flask/app.py", line 1718, in handle_user_exception
    reraise(exc_type, exc_value, tb)
  File "/home/razor/TruckNLoad/Truck-n-Load/venv/lib/python3.6/site-packages/flask/_compat.py", line 35, in reraise
    raise value
  File "/home/razor/TruckNLoad/Truck-n-Load/venv/lib/python3.6/site-packages/flask/app.py", line 1813, in full_dispatch_request
    rv = self.dispatch_request()
  File "/home/razor/TruckNLoad/Truck-n-Load/venv/lib/python3.6/site-packages/flask/app.py", line 1799, in dispatch_request
    return self.view_functions[rule.endpoint](**req.view_args)
  File "/home/razor/TruckNLoad/Truck-n-Load/venv/lib/python3.6/site-packages/flask_login/utils.py", line 261, in decorated_view
    return func(*args, **kwargs)
  File "/home/razor/TruckNLoad/Truck-n-Load/app/routes.py", line 163, in pan_preparation
    return redirect(url_for('pallet_creator', delivery_id=form.delivery_id.data))
AttributeError: 'DeliverySelectorForm' object has no attribute 'delivery_id'
[2018-06-04 18:24:42,611] [3809] {/home/razor/TruckNLoad/Truck-n-Load/venv/lib/python3.6/site-packages/flask/app.py:1761} ERROR - Exception on /administration/customer_creator [POST]
Traceback (most recent call last):
  File "/home/razor/TruckNLoad/Truck-n-Load/venv/lib/python3.6/site-packages/sqlalchemy/engine/base.py", line 1193, in _execute_context
    context)
  File "/home/razor/TruckNLoad/Truck-n-Load/venv/lib/python3.6/site-packages/sqlalchemy/engine/default.py", line 507, in do_execute
    cursor.execute(statement, parameters)
psycopg2.IntegrityError: duplicate key value violates unique constraint "customer_Email_key"
DETAIL:  Key ("Email")=(JackSparrow@hotmail.com) already exists.


The above exception was the direct cause of the following exception:

Traceback (most recent call last):
  File "/home/razor/TruckNLoad/Truck-n-Load/venv/lib/python3.6/site-packages/flask/app.py", line 2292, in wsgi_app
    response = self.full_dispatch_request()
  File "/home/razor/TruckNLoad/Truck-n-Load/venv/lib/python3.6/site-packages/flask/app.py", line 1815, in full_dispatch_request
    rv = self.handle_user_exception(e)
  File "/home/razor/TruckNLoad/Truck-n-Load/venv/lib/python3.6/site-packages/flask/app.py", line 1718, in handle_user_exception
    reraise(exc_type, exc_value, tb)
  File "/home/razor/TruckNLoad/Truck-n-Load/venv/lib/python3.6/site-packages/flask/_compat.py", line 35, in reraise
    raise value
  File "/home/razor/TruckNLoad/Truck-n-Load/venv/lib/python3.6/site-packages/flask/app.py", line 1813, in full_dispatch_request
    rv = self.dispatch_request()
  File "/home/razor/TruckNLoad/Truck-n-Load/venv/lib/python3.6/site-packages/flask/app.py", line 1799, in dispatch_request
    return self.view_functions[rule.endpoint](**req.view_args)
  File "/home/razor/TruckNLoad/Truck-n-Load/venv/lib/python3.6/site-packages/flask_login/utils.py", line 261, in decorated_view
    return func(*args, **kwargs)
  File "/home/razor/TruckNLoad/Truck-n-Load/app/routes.py", line 149, in customer_creator
    db.session.commit()
  File "/home/razor/TruckNLoad/Truck-n-Load/venv/lib/python3.6/site-packages/sqlalchemy/orm/scoping.py", line 153, in do
    return getattr(self.registry(), name)(*args, **kwargs)
  File "/home/razor/TruckNLoad/Truck-n-Load/venv/lib/python3.6/site-packages/sqlalchemy/orm/session.py", line 943, in commit
    self.transaction.commit()
  File "/home/razor/TruckNLoad/Truck-n-Load/venv/lib/python3.6/site-packages/sqlalchemy/orm/session.py", line 467, in commit
    self._prepare_impl()
  File "/home/razor/TruckNLoad/Truck-n-Load/venv/lib/python3.6/site-packages/sqlalchemy/orm/session.py", line 447, in _prepare_impl
    self.session.flush()
  File "/home/razor/TruckNLoad/Truck-n-Load/venv/lib/python3.6/site-packages/sqlalchemy/orm/session.py", line 2254, in flush
    self._flush(objects)
  File "/home/razor/TruckNLoad/Truck-n-Load/venv/lib/python3.6/site-packages/sqlalchemy/orm/session.py", line 2380, in _flush
    transaction.rollback(_capture_exception=True)
  File "/home/razor/TruckNLoad/Truck-n-Load/venv/lib/python3.6/site-packages/sqlalchemy/util/langhelpers.py", line 66, in __exit__
    compat.reraise(exc_type, exc_value, exc_tb)
  File "/home/razor/TruckNLoad/Truck-n-Load/venv/lib/python3.6/site-packages/sqlalchemy/util/compat.py", line 187, in reraise
    raise value
  File "/home/razor/TruckNLoad/Truck-n-Load/venv/lib/python3.6/site-packages/sqlalchemy/orm/session.py", line 2344, in _flush
    flush_context.execute()
  File "/home/razor/TruckNLoad/Truck-n-Load/venv/lib/python3.6/site-packages/sqlalchemy/orm/unitofwork.py", line 391, in execute
    rec.execute(self)
  File "/home/razor/TruckNLoad/Truck-n-Load/venv/lib/python3.6/site-packages/sqlalchemy/orm/unitofwork.py", line 556, in execute
    uow
  File "/home/razor/TruckNLoad/Truck-n-Load/venv/lib/python3.6/site-packages/sqlalchemy/orm/persistence.py", line 181, in save_obj
    mapper, table, insert)
  File "/home/razor/TruckNLoad/Truck-n-Load/venv/lib/python3.6/site-packages/sqlalchemy/orm/persistence.py", line 866, in _emit_insert_statements
    execute(statement, params)
  File "/home/razor/TruckNLoad/Truck-n-Load/venv/lib/python3.6/site-packages/sqlalchemy/engine/base.py", line 948, in execute
    return meth(self, multiparams, params)
  File "/home/razor/TruckNLoad/Truck-n-Load/venv/lib/python3.6/site-packages/sqlalchemy/sql/elements.py", line 269, in _execute_on_connection
    return connection._execute_clauseelement(self, multiparams, params)
  File "/home/razor/TruckNLoad/Truck-n-Load/venv/lib/python3.6/site-packages/sqlalchemy/engine/base.py", line 1060, in _execute_clauseelement
    compiled_sql, distilled_params
  File "/home/razor/TruckNLoad/Truck-n-Load/venv/lib/python3.6/site-packages/sqlalchemy/engine/base.py", line 1200, in _execute_context
    context)
  File "/home/razor/TruckNLoad/Truck-n-Load/venv/lib/python3.6/site-packages/sqlalchemy/engine/base.py", line 1413, in _handle_dbapi_exception
    exc_info
  File "/home/razor/TruckNLoad/Truck-n-Load/venv/lib/python3.6/site-packages/sqlalchemy/util/compat.py", line 203, in raise_from_cause
    reraise(type(exception), exception, tb=exc_tb, cause=cause)
  File "/home/razor/TruckNLoad/Truck-n-Load/venv/lib/python3.6/site-packages/sqlalchemy/util/compat.py", line 186, in reraise
    raise value.with_traceback(tb)
  File "/home/razor/TruckNLoad/Truck-n-Load/venv/lib/python3.6/site-packages/sqlalchemy/engine/base.py", line 1193, in _execute_context
    context)
  File "/home/razor/TruckNLoad/Truck-n-Load/venv/lib/python3.6/site-packages/sqlalchemy/engine/default.py", line 507, in do_execute
    cursor.execute(statement, parameters)
sqlalchemy.exc.IntegrityError: (psycopg2.IntegrityError) duplicate key value violates unique constraint "customer_Email_key"
DETAIL:  Key ("Email")=(JackSparrow@hotmail.com) already exists.
 [SQL: 'INSERT INTO customer ("First Name", "Last Name", "Email", "Address", "Phone Number") VALUES (%(First Name)s, %(Last Name)s, %(Email)s, %(Address)s, %(Phone Number)s) RETURNING customer.id'] [parameters: {'First Name': 'Jack', 'Last Name': 'Sparrow', 'Email': 'JackSparrow@hotmail.com', 'Address': '42 Hay Street, WA', 'Phone Number': '0123445667'}] (Background on this error at: http://sqlalche.me/e/gkpj)
